<?xml version="1.0" encoding="UTF-8"?>
<!-- Generated by org.testng.reporters.JUnitReportReporter -->
<testsuite hostname="Personal" failures="2" tests="6" name="testSuite.E2E.TestFunctionalityB" time="150.571" errors="0" timestamp="24 Sep 2018 16:05:15 GMT" skipped="0">
  <testcase classname="testSuite.E2E.TestFunctionalityB" name="test5" time="45.367"/>
  <testcase classname="testSuite.E2E.TestFunctionalityB" name="test5" time="47.121"/>
  <testcase classname="testSuite.E2E.TestFunctionalityB" name="test6" time="5.921">
    <failure message="Supposed to be failed expected [true] but found [false]" type="java.lang.AssertionError">
      <![CDATA[java.lang.AssertionError: Supposed to be failed expected [true] but found [false]
at org.testng.Assert.fail(Assert.java:96)
at org.testng.Assert.failNotEquals(Assert.java:776)
at org.testng.Assert.assertTrue(Assert.java:44)
at testSuite.E2E.TestFunctionalityB.test6(TestFunctionalityB.java:32)
at java.base/jdk.internal.reflect.NativeMethodAccessorImpl.invoke0(Native Method)
at java.base/jdk.internal.reflect.NativeMethodAccessorImpl.invoke(Unknown Source)
at java.base/jdk.internal.reflect.DelegatingMethodAccessorImpl.invoke(Unknown Source)
at java.base/java.lang.reflect.Method.invoke(Unknown Source)
at org.testng.internal.MethodInvocationHelper.invokeMethod(MethodInvocationHelper.java:124)
at org.testng.internal.Invoker.invokeMethod(Invoker.java:583)
at org.testng.internal.Invoker.invokeTestMethod(Invoker.java:719)
at org.testng.internal.Invoker.invokeTestMethods(Invoker.java:989)
at org.testng.internal.TestMethodWorker.invokeTestMethods(TestMethodWorker.java:125)
at org.testng.internal.TestMethodWorker.run(TestMethodWorker.java:109)
at java.base/java.util.concurrent.ThreadPoolExecutor.runWorker(Unknown Source)
at java.base/java.util.concurrent.ThreadPoolExecutor$Worker.run(Unknown Source)
at java.base/java.lang.Thread.run(Unknown Source)
]]>
    </failure>
  </testcase> <!-- test6 -->
  <testcase classname="testSuite.E2E.TestFunctionalityB" name="test6" time="15.689">
    <failure message="Supposed to be failed expected [true] but found [false]" type="java.lang.AssertionError">
      <![CDATA[java.lang.AssertionError: Supposed to be failed expected [true] but found [false]
at org.testng.Assert.fail(Assert.java:96)
at org.testng.Assert.failNotEquals(Assert.java:776)
at org.testng.Assert.assertTrue(Assert.java:44)
at testSuite.E2E.TestFunctionalityB.test6(TestFunctionalityB.java:32)
at java.base/jdk.internal.reflect.NativeMethodAccessorImpl.invoke0(Native Method)
at java.base/jdk.internal.reflect.NativeMethodAccessorImpl.invoke(Unknown Source)
at java.base/jdk.internal.reflect.DelegatingMethodAccessorImpl.invoke(Unknown Source)
at java.base/java.lang.reflect.Method.invoke(Unknown Source)
at org.testng.internal.MethodInvocationHelper.invokeMethod(MethodInvocationHelper.java:124)
at org.testng.internal.Invoker.invokeMethod(Invoker.java:583)
at org.testng.internal.Invoker.invokeTestMethod(Invoker.java:719)
at org.testng.internal.Invoker.invokeTestMethods(Invoker.java:989)
at org.testng.internal.TestMethodWorker.invokeTestMethods(TestMethodWorker.java:125)
at org.testng.internal.TestMethodWorker.run(TestMethodWorker.java:109)
at java.base/java.util.concurrent.ThreadPoolExecutor.runWorker(Unknown Source)
at java.base/java.util.concurrent.ThreadPoolExecutor$Worker.run(Unknown Source)
at java.base/java.lang.Thread.run(Unknown Source)
]]>
    </failure>
  </testcase> <!-- test6 -->
  <testcase classname="testSuite.E2E.TestFunctionalityB" name="test4" time="13.813"/>
  <testcase classname="testSuite.E2E.TestFunctionalityB" name="test4" time="22.660"/>
</testsuite> <!-- testSuite.E2E.TestFunctionalityB -->
